Workbook

Sheet Cover
B2: FINDINGS REGISTER & 90-DAY REMEDIATION ROADMAP
B3: SOC 2 Type 1 Readiness Assessment
B5: Client (Simulated): | C5: MeridianHealth Analytics Pty Ltd
B6: Engagement: | C6: MHA-SOC2-2026-001
B7: Total Findings: | C7: 22 (4 High, 18 Medium, including informational Lows)
B8: Remediation Window: | C8: 90 days (29 April 2026 – 28 July 2026)
B9: Sprint Cadence: | C9: 6 two-week sprints
B10: Prepared By: | C10: Gaurav Govind, GRC Analyst
B11: Date: | C11: 28 April 2026
B12: Version: | C12: 1.0 — Final
B13: Classification: | C13: Confidential — Client
B16: WORKBOOK CONTENTS
B17: Cover | C17: This sheet
B18: Findings Register | C18: All 22 findings with severity, owner, effort, target date, status
B19: 90-Day Roadmap | C19: Sprint-by-sprint sequencing of remediation
B20: Effort Summary | C20: Effort metrics by severity, owner, and sprint (formulas)
B21: Status Tracker | C21: Tracking template for remediation progress

Sheet Findings Register
A1: Finding ID | B1: Control Ref | C1: Finding Title | D1: Severity | E1: CC | F1: Description | G1: Recommendation | H1: Owner | I1: Effort (days) | J1: Sprint | K1: Target Date | L1: Status
A2: F-001 | B2: CC1.4-02 | C2: Incomplete security awareness training & no phishing simulation | D2: High | E2: CC1 | F2: KnowBe4 deployed but completion at 78% (target 100%); phishing simulation feature not enabled. | G2: Drive completion to 100% before audit period; enable monthly phishing simulations; retain per-user evidence. | H2: CISO | I2: 5 | J2: Sprint 1 | K2: 31 March 2026 | L2: Open
A3: F-002 | B3: CC2.3-02 | C3: No defined customer incident notification SLA | D3: High | E3: CC2 | F3: MSA references 'reasonable timeframes' rather than a contractual SLA; US healthcare clients expect 72-hour notice. | G3: Define and contractually commit to 72-hour incident notification SLA; update MSA template; communicate to existing customers. | H3: CISO / General Counsel | I3: 8 | J3: Sprint 1 | K3: 31 March 2026 | L3: Open
A4: F-003 | B4: CC6.2-01 | C4: Annual access reviews fall short of SOC 2 audit expectation | D4: High | E4: CC6 | F4: Production AWS, Okta, GitHub, and database access reviewed annually; SOC 2 audit pattern is quarterly with retained manager sign-off. | G4: Move to quarterly access reviews; build manager sign-off workflow in Vanta or ServiceNow; retain evidence. | H4: CISO / People & Culture | I4: 10 | J4: Sprint 1 | K4: 31 March 2026 | L4: Open
A5: F-004 | B5: CC9.2-04 | C5: No CUEC tracker for sub-service organisations | D5: High | E5: CC9 | F5: AWS, Okta, Datadog SOC 2 reports collected but Complementary User Entity Controls not formally mapped or tracked. | G5: Build CUEC tracker mapping each sub-service organisation user-entity-control consideration to a MeridianHealth control; review on each new SOC report. | H5: CISO | I5: 6 | J5: Sprint 1 | K5: 31 March 2026 | L5: Open
A6: F-005 | B6: CC1.2-01 | C6: No Board-level Information Security Charter | D6: Medium | E6: CC1 | F6: Quarterly security update on Board agenda since Q3 FY24, but no documented Board-level Security Charter or Risk Appetite Statement. | G6: Draft and adopt a Board-approved Information Security Charter and Risk Appetite Statement aligned with US assurance expectations. | H6: CISO / Board Secretary | I6: 4 | J6: Sprint 2 | K6: 14 April 2026 | L6: Open
A7: F-006 | B7: CC2.3-01 | C7: No customer-facing Trust Centre | D7: Medium | E7: CC2 | F7: MSA includes generic security clauses; no customer-facing Trust Centre or security commitments page. | G7: Build customer-facing Trust Centre publishing SOC 2 status, ISO 27001 certificate, and incident notification commitments. | H7: CISO / Marketing | I7: 12 | J7: Sprint 3 | K7: 28 April 2026 | L7: Open
A8: F-007 | B8: CC3.2-02 | C8: No formal fraud risk assessment | D8: Medium | E8: CC3 | F8: No formal fraud risk assessment documented; fraud risk covered informally by Finance. | G8: Conduct an annual fraud risk assessment covering financial, operational, and IT-fraud scenarios; document and link to risk register. | H8: CFO / CISO | I8: 6 | J8: Sprint 2 | K8: 14 April 2026 | L8: Open
A9: F-008 | B9: CC4.1-01 | C9: No independent internal audit function | D9: Medium | E9: CC4 | F9: Internal audit performed by CISO team annually; not independent of management. | G9: Engage external internal-audit provider for FY26; alternatively rotate auditor across leadership. | H9: CISO / Audit Committee | I9: 8 | J9: Sprint 4 | K9: 12 May 2026 | L9: Open
A10: F-009 | B10: CC5.3-01 | C10: Stale policies awaiting review | D10: Medium | E10: CC5 | F10: Four policies (DLP, Cryptography, Mobile Device, Acceptable Use) are over 24 months old without review. | G10: Refresh stale policies; implement annual policy review cadence; adopt Vanta or Drata acknowledgement workflow. | H10: CISO | I10: 10 | J10: Sprint 2 | K10: 14 April 2026 | L10: Open
A11: F-010 | B11: CC5.3-02 | C11: Segregation of Duties not formally documented | D11: Medium | E11: CC5 | F11: Production deployment requires peer review in GitHub; SoD not formally documented across deployment, access, and financial approvals. | G11: Document SoD matrix covering deployment, access provisioning, and financial approvals; review quarterly. | H11: CTO / CISO | I11: 5 | J11: Sprint 3 | K11: 28 April 2026 | L11: Open
A12: F-011 | B12: CC6.1-03 | C12: No PAM tool for OS-level admin access | D12: Medium | E12: CC6 | F12: AWS admin via IAM Identity Center with break-glass; no PAM tool for OS-level admin on EC2. | G12: Implement Teleport or AWS Systems Manager Session Manager for OS-level access with session recording. | H12: Security Engineering | I12: 15 | J12: Sprint 4 | K12: 12 May 2026 | L12: Open
A13: F-012 | B13: CC6.1-04 | C13: No service account inventory | D13: Medium | E13: CC6 | F13: Service accounts exist in AWS IAM and GitHub; no central inventory or owner mapping. | G13: Build service account inventory with owner, purpose, last-used date; review quarterly. | H13: Security Engineering | I13: 7 | J13: Sprint 3 | K13: 28 April 2026 | L13: Open
... A23: F-022 | B23: CC1.1-01 | C23: Manual training acknowledgement tracking | D23: Low | E23: CC1 | F23: Code of Conduct annual acknowledgement tracked in BambooHR with partial manual export. | G23: Automate acknowledgement evidence export from BambooHR; integrate into Vanta evidence collection. | H23: People & Culture | I23: 3 | J23: Sprint 5 | K23: 26 May 2026 | L23: Open

Sheet 90-Day Roadmap
B2: 90-DAY REMEDIATION ROADMAP
B3: 6 two-week sprints — sequenced by severity and dependency
B5: Sprint 1 — 29 Apr – 12 May 2026
B6: Theme: Quick wins & High-severity remediation — Close all High findings to remove audit-blocking issues.
B7: ID | C7: Finding | D7: Severity | E7: Owner | F7: Effort (d) | G7: Target Date
B8: F-001 | C8: Incomplete security awareness training & no phishing simulation | D8: High | E8: CISO | F8: 5 | G8: 31 March 2026
B9: F-002 | C9: No defined customer incident notification SLA | D9: High | E9: CISO / General Counsel | F9: 8 | G9: 31 March 2026
B10: F-003 | C10: Annual access reviews fall short of SOC 2 audit expectation | D10: High | E10: CISO / People & Culture | F10: 10 | G10: 31 March 2026
B11: F-004 | C11: No CUEC tracker for sub-service organisations | D11: High | E11: CISO | F11: 6 | G11: 31 March 2026
B12: F-013 | C12: Vulnerability remediation backlog | D12: Medium | E12: Security Engineering | F12: 8 | G12: 31 March 2026
B13: F-014 | C13: Incident response tabletop overdue | D13: Medium | E13: CISO | F13: 4 | G13: 31 March 2026
B14: Sprint total: 6 findings, 41 days effort
B16: Sprint 2 — 13 May – 26 May 2026
B17: Theme: Governance & policies — Refresh stale policies; charter Board oversight; formalise fraud risk.
B18: ID | C18: Finding | D18: Severity | E18: Owner | F18: Effort (d) | G18: Target Date
B19: F-005 | C19: No Board-level Information Security Charter | D19: Medium | E19: CISO / Board Secretary | F19: 4 | G19: 14 April 2026
B20: F-007 | C20: No formal fraud risk assessment | D20: Medium | E20: CFO / CISO | F20: 6 | G20: 14 April 2026
B21: F-009 | C21: Stale policies awaiting review | D21: Medium | E21: CISO | F21: 10 | G21: 14 April 2026
B22: F-016 | C22: Backup recovery not recently tested | D22: Medium | E22: Platform Engineering | F22: 6 | G22: 14 April 2026
B23: F-017 | C23: Change evidence retention below audit expectation | D23: Medium | E23: Engineering | F23: 4 | G23: 14 April 2026
B24: Sprint total: 5 findings, 30 days effort
B26: Sprint 3 — 27 May – 9 Jun 2026
B27: Theme: Process formalisation — Trust Centre, SoD matrix, service account inventory, comms playbook.
B28: ID | C28: Finding | D28: Severity | E28: Owner | F28: Effort (d) | G28: Target Date
B29: F-006 | C29: No customer-facing Trust Centre | D29: Medium | E29: CISO / Marketing | F29: 12 | G29: 28 April 2026
B30: F-010 | C30: Segregation of Duties not formally documented | D30: Medium | E30: CTO / CISO | F30: 5 | G30: 28 April 2026
B31: F-012 | C31: No service account inventory | D31: Medium | E31: Security Engineering | F31: 7 | G31: 28 April 2026
B32: F-015 | C32: No customer communications playbook | D32: Medium | E32: CISO / Marketing | F32: 5 | G32: 28 April 2026
B33: F-020 | C33: No continuous vendor monitoring | D33: Medium | E33: Procurement / CISO | F33: 5 | G33: 28 April 2026
B34: Sprint total: 5 findings, 34 days effort
B36: Sprint 4 — 10 Jun – 23 Jun 2026
B37: Theme: Resilience & PAM — BCP/DR testing, PAM rollout, internal audit engagement.
B38: ID | C38: Finding | D38: Severity | E38: Owner | F38: Effort (d) | G38: Target Date
B39: F-008 | C39: No independent internal audit function | D39: Medium | E39: CISO / Audit Committee | F39: 8 | G39: 12 May 2026
B40: F-011 | C40: No PAM tool for OS-level admin access | D40: Medium | E40: Security Engineering | F40: 15 | G40: 12 May 2026
B41: F-018 | C41: BCP not tested in last 12 months | D41: Medium | E41: COO / CISO | F41: 6 | G41: 12 May 2026
B42: F-019 | C42: DR cross-region failover untested | D42: Medium | E42: Platform Engineering | F42: 10 | G42: 12 May 2026
B43: Sprint total: 4 findings, 39 days effort
B45: Sprint 5 — 24 Jun – 7 Jul 2026
B46: Theme: Data lifecycle & automation — Automated retention/deletion; awareness evidence automation.
...

Sheet Effort Summary
B2: EFFORT SUMMARY
B4: BY SEVERITY
B5: Severity | C5: Count | D5: Total Effort (days) | E5: Avg Effort (days)
B6: High | C6: =COUNTIF('Findings Register'!D2:D23,"High") -> 4 | D6: =SUMIF('Findings Register'!D2:D23,"High",'Findings Register'!I2:I23) -> 29 | E6: =IFERROR(D6/C6,0) -> 7.25
B7: Medium | C7: =COUNTIF('Findings Register'!D2:D23,"Medium") -> 17 | D7: =SUMIF('Findings Register'!D2:D23,"Medium",'Findings Register'!I2:I23) -> 123 | E7: =IFERROR(D7/C7,0) -> 7.2352941
B8: Low | C8: =COUNTIF('Findings Register'!D2:D23,"Low") -> 1 | D8: =SUMIF('Findings Register'!D2:D23,"Low",'Findings Register'!I2:I23) -> 3 | E8: =IFERROR(D8/C8,0) -> 3
B9: TOTAL | C9: =SUM(C6:C8) -> 22 | D9: =SUM(D6:D8) -> 155 | E9: =IFERROR(D9/C9,0) -> 7.0454545
B12: BY SPRINT
B13: Sprint | C13: Count | D13: Total Effort (days)
B14: Sprint 1 | C14: =COUNTIF('Findings Register'!J2:J23,"Sprint 1") -> 6 | D14: =SUMIF('Findings Register'!J2:J23,"Sprint 1",'Findings Register'!I2:I23) -> 41
B15: Sprint 2 | C15: =COUNTIF('Findings Register'!J2:J23,"Sprint 2") -> 5 | D15: =SUMIF('Findings Register'!J2:J23,"Sprint 2",'Findings Register'!I2:I23) -> 30
B16: Sprint 3 | C16: =COUNTIF('Findings Register'!J2:J23,"Sprint 3") -> 5 | D16: =SUMIF('Findings Register'!J2:J23,"Sprint 3",'Findings Register'!I2:I23) -> 34
B17: Sprint 4 | C17: =COUNTIF('Findings Register'!J2:J23,"Sprint 4") -> 4 | D17: =SUMIF('Findings Register'!J2:J23,"Sprint 4",'Findings Register'!I2:I23) -> 39
B18: Sprint 5 | C18: =COUNTIF('Findings Register'!J2:J23,"Sprint 5") -> 2 | D18: =SUMIF('Findings Register'!J2:J23,"Sprint 5",'Findings Register'!I2:I23) -> 11
B19: Sprint 6 | C19: =COUNTIF('Findings Register'!J2:J23,"Sprint 6") -> 0 | D19: =SUMIF('Findings Register'!J2:J23,"Sprint 6",'Findings Register'!I2:I23) -> 0
B20: TOTAL | C20: =SUM(C14:C19) -> 22 | D20: =SUM(D14:D19) -> 155
B23: BY OWNER (TOP CONTRIBUTORS)
B24: Owner | C24: Count | D24: Total Effort (days)
B25: Security Engineering | C25: =COUNTIF('Findings Register'!H2:H23,"Security Engineering") -> 3 | D25: =SUMIF('Findings Register'!H2:H23,"Security Engineering",'Findings Register'!I2:I23) -> 30
B26: CISO | C26: =COUNTIF('Findings Register'!H2:H23,"CISO") -> 4 | D26: =SUMIF('Findings Register'!H2:H23,"CISO",'Findings Register'!I2:I23) -> 25
B27: CISO / Marketing | C27: =COUNTIF('Findings Register'!H2:H23,"CISO / Marketing") -> 2 | D27: =SUMIF('Findings Register'!H2:H23,"CISO / Marketing",'Findings Register'!I2:I23) -> 17
B28: Platform Engineering | C28: =COUNTIF('Findings Register'!H2:H23,"Platform Engineering") -> 2 | D28: =SUMIF('Findings Register'!H2:H23,"Platform Engineering",'Findings Register'!I2:I23) -> 16
B29: CISO / People & Culture | C29: =COUNTIF('Findings Register'!H2:H23,"CISO / People & Culture") -> 1 | D29: =SUMIF('Findings Register'!H2:H23,"CISO / People & Culture",'Findings Register'!I2:I23) -> 10
B30: CISO / General Counsel | C30: =COUNTIF('Findings Register'!H2:H23,"CISO / General Counsel") -> 1 | D30: =SUMIF('Findings Register'!H2:H23,"CISO / General Counsel",'Findings Register'!I2:I23) -> 8
B31: CISO / Audit Committee | C31: =COUNTIF('Findings Register'!H2:H23,"CISO / Audit Committee") -> 1 | D31: =SUMIF('Findings Register'!H2:H23,"CISO / Audit Committee",'Findings Register'!I2:I23) -> 8
B32: CISO / Platform Engineering | C32: =COUNTIF('Findings Register'!H2:H23,"CISO / Platform Engineering") -> 1 | D32: =SUMIF('Findings Register'!H2:H23,"CISO / Platform Engineering",'Findings Register'!I2:I23) -> 8
B33: CFO / CISO | C33: =COUNTIF('Findings Register'!H2:H23,"CFO / CISO") -> 1 | D33: =SUMIF('Findings Register'!H2:H23,"CFO / CISO",'Findings Register'!I2:I23) -> 6
B34: COO / CISO | C34: =COUNTIF('Findings Register'!H2:H23,"COO / CISO") -> 1 | D34: =SUMIF('Findings Register'!H2:H23,"COO / CISO",'Findings Register'!I2:I23) -> 6
B35: CTO / CISO | C35: =COUNTIF('Findings Register'!H2:H23,"CTO / CISO") -> 1 | D35: =SUMIF('Findings Register'!H2:H23,"CTO / CISO",'Findings Register'!I2:I23) -> 5
B36: Procurement / CISO | C36: =COUNTIF('Findings Register'!H2:H23,"Procurement / CISO") -> 1 | D36: =SUMIF('Findings Register'!H2:H23,"Procurement / CISO",'Findings Register'!I2:I23) -> 5
B37: CISO / Board Secretary | C37: =COUNTIF('Findings Register'!H2:H23,"CISO / Board Secretary") -> 1 | D37: =SUMIF('Findings Register'!H2:H23,"CISO / Board Secretary",'Findings Register'!I2:I23) -> 4
B38: Engineering | C38: =COUNTIF('Findings Register'!H2:H23,"Engineering") -> 1 | D38: =SUMIF('Findings Register'!H2:H23,"Engineering",'Findings Register'!I2:I23) -> 4
B39: People & Culture | C39: =COUNTIF('Findings Register'!H2:H23,"People & Culture") -> 1 | D39: =SUMIF('Findings Register'!H2:H23,"People & Culture",'Findings Register'!I2:I23) -> 3

Sheet Status Tracker
B2: STATUS TRACKER
B3: Update Status column on the Findings Register sheet; this view auto-recalculates.
B5: OVERALL STATUS
B6: Status | C6: Count | D6: %
B7: Open | C7: =COUNTIF('Findings Register'!L2:L23,"Open") -> 22 | D7: =IFERROR(C7/SUM($C$7:$C$9),0) -> 1
B8: In Progress | C8: =COUNTIF('Findings Register'!L2:L23,"In Progress") -> 0 | D8: =IFERROR(C8/SUM($C$7:$C$9),0) -> 0
B9: Closed | C9: =COUNTIF('Findings Register'!L2:L23,"Closed") -> 0 | D9: =IFERROR(C9/SUM($C$7:$C$9),0) -> 0
B12: REMAINING OPEN BY SEVERITY
B13: Severity | C13: Open Count | D13: Of Total | E13: % Remaining
B14: High | C14: =COUNTIFS('Findings Register'!D2:D23,"High",'Findings Register'!L2:L23,"Open") -> 4 | D14: =COUNTIF('Findings Register'!D2:D23,"High") -> 4 | E14: =IFERROR(C14/D14,0) -> 1
B15: Medium | C15: =COUNTIFS('Findings Register'!D2:D23,"Medium",'Findings Register'!L2:L23,"Open") -> 17 | D15: =COUNTIF('Findings Register'!D2:D23,"Medium") -> 17 | E15: =IFERROR(C15/D15,0) -> 1
B16: Low | C16: =COUNTIFS('Findings Register'!D2:D23,"Low",'Findings Register'!L2:L23,"Open") -> 1 | D16: =COUNTIF('Findings Register'!D2:D23,"Low") -> 1 | E16: =IFERROR(C16/D16,0) -> 1
